Workbook

Sheet 📋 INSTRUCCIONES
A1: 📋 INSTRUCCIONES DE USO
A2: Guía rápida del sistema — DTE | Dirección de Tecnología Educativa | 2026
B3: Hoja | C3: Función | D3: Uso | E3: Responsable
B4: 👥 ESTUDIANTES | C4: Datos de los 12 alumnos y roles actuales | D4: Configuración inicial + rol semanal | E4: FED
B5: 📅 ASISTENCIA | C5: Registro de presencia por sesión | D5: Carga al inicio de cada sesión | E5: Líder de Equipo
B6: 🔧 OT | C6: Órdenes de trabajo de cada netbook | D6: Carga durante y al cierre | E6: Documentador
B7: 💻 EQUIPOS | C7: Inventario y estado de cada netbook | D7: Actualizar al cambiar de etapa | E7: Técnico Principal
B8: ⚙️ ROLES | C8: Rotación semanal de roles | D8: Consulta semanal | E8: Todos
B9: 📊 KANBAN | C9: Tablero visual de etapas | D9: Mover al cambiar estado | E9: Líder de Equipo
B10: 🏆 DASHBOARD | C10: Indicadores globales automáticos | D10: Solo lectura | E10: FED
B11: 🏅 RANKING | C11: Registro de puntos grupales e individuales | D11: Solo lectura | E11: FED
B14: 📌 FLUJO DE TRABAJO POR SESIÓN
B15: 1️⃣ Líder registra asistencia en ASISTENCIA al iniciar la sesión
B16: 2️⃣ Al recibir un equipo: cargarlo en EQUIPOS y abrir OT en hoja OT
B17: 3️⃣ Técnico Principal ejecuta desbloqueo — Documentador registra en OT en tiempo real
B18: 4️⃣ Tester/Instalador prepara y ejecuta la instalación de imagen del SO
B19: 5️⃣ Al cambiar de etapa: Documentador actualiza Estado Final en OT
B20: 6️⃣ Control de Calidad verifica y autoriza cada avance antes de continuar
B21: 7️⃣ Al cierre: Documentador completa el historial — Líder actualiza horas en OT
B22: 8️⃣ FED revisa el DASHBOARD para ver el estado global del taller

Sheet 📅 ASISTENCIA
A1: 📅 REGISTRO DE ASISTENCIA
A2: Grupo 1 (Lunes y Miércoles) arriba | Grupo 2 (Martes y Jueves) abajo
A4: GRUPO 1 — Lunes y Miércoles
A5: # | B5: Fecha | C5: Sesión N° | D5: Kovach, Ludmila | E5: Terraza, Brian | F5: Pedrozo, Lorena | G5: Cáceres, Santiago | H5: Aguilera, Thiago | I5: Simonetti, Tomás | J5: Presentes | K5: Ausentes | L5: % Asist.
A6: 1 | B6: 46190 | C6: 1 | D6: Presente | E6: Presente | F6: Presente | G6: Ausente | H6: Presente | I6: Presente | J6: =COUNTIF(D6:I6,"Presente")+COUNTIF(D6:I6,"Tardanza") -> 5 | K6: =COUNTIF(D6:I6,"Ausente") -> 1 | L6: =IFERROR(J6/6,0) -> 0.83333333
A7: 2 | B7: 46195 | C7: 2 | D7: Presente | E7: Presente | F7: Presente | G7: Ausente | H7: Presente | I7: Presente | J7: =COUNTIF(D7:I7,"Presente")+COUNTIF(D7:I7,"Tardanza") -> 5 | K7: =COUNTIF(D7:I7,"Ausente") -> 1 | L7: =IFERROR(J7/6,0) -> 0.83333333
A8: 3 | B8: 46197 | C8: 3 | D8: Presente | E8: Presente | F8: Presente | G8: Presente | H8: Presente | I8: Presente | J8: =COUNTIF(D8:I8,"Presente")+COUNTIF(D8:I8,"Tardanza") -> 6 | K8: =COUNTIF(D8:I8,"Ausente") -> 0 | L8: =IFERROR(J8/6,0) -> 1
A9: 4 | B9: 46202 | C9: 4 | D9: Presente | E9: Presente | F9: Presente | G9: Presente | H9: Presente | I9: Presente | J9: =COUNTIF(D9:I9,"Presente")+COUNTIF(D9:I9,"Tardanza") -> 6 | K9: =COUNTIF(D9:I9,"Ausente") -> 0 | L9: =IFERROR(J9/6,0) -> 1
A10: 5 | B10: 46204 | C10: 5 | D10: Tardanza | E10: Presente | F10: Presente | G10: Presente | H10: Presente | I10: Presente | J10: =COUNTIF(D10:I10,"Presente")+COUNTIF(D10:I10,"Tardanza") -> 6 | K10: =COUNTIF(D10:I10,"Ausente") -> 0 | L10: =IFERROR(J10/6,0) -> 1
A11: 6 | B11: 46209 | C11: 6 | D11: Justificado | E11: Presente | F11: Presente | G11: Presente | H11: Presente | I11: Ausente | J11: =COUNTIF(D11:I11,"Presente")+COUNTIF(D11:I11,"Tardanza") -> 4 | K11: =COUNTIF(D11:I11,"Ausente") -> 1 | L11: =IFERROR(J11/6,0) -> 0.66666667
A12: 7 | B12: 46211 | C12: 7 | D12: Ausente | E12: Presente | F12: Presente | G12: Presente | H12: Presente | I12: Presente | J12: =COUNTIF(D12:I12,"Presente")+COUNTIF(D12:I12,"Tardanza") -> 5 | K12: =COUNTIF(D12:I12,"Ausente") -> 1 | L12: =IFERROR(J12/6,0) -> 0.83333333
A13: 8 | B13: 46216 | C13: 8 | D13: Presente | E13: Presente | F13: Presente | G13: Presente | H13: Presente | I13: Presente | J13: =COUNTIF(D13:I13,"Presente")+COUNTIF(D13:I13,"Tardanza") -> 6 | K13: =COUNTIF(D13:I13,"Ausente") -> 0 | L13: =IFERROR(J13/6,0) -> 1
A14: 9 | B14: 46218 | C14: 9 | D14: Ausente | E14: Ausente | F14: Tardanza | G14: Presente | H14: Presente | I14: Presente | J14: =COUNTIF(D14:I14,"Presente")+COUNTIF(D14:I14,"Tardanza") -> 4 | K14: =COUNTIF(D14:I14,"Ausente") -> 2 | L14: =IFERROR(J14/6,0) -> 0.66666667
A15: 10 | B15: 46237 | C15: 10 | D15: Ausente | E15: Ausente | F15: Presente | G15: Presente | H15: Presente | I15: Ausente | J15: =COUNTIF(D15:I15,"Presente")+COUNTIF(D15:I15,"Tardanza") -> 3 | K15: =COUNTIF(D15:I15,"Ausente") -> 3 | L15: =IFERROR(J15/6,0) -> 0.5
A16: 11 | B16: 46244 | C16: 11 | D16: Ausente | E16: Presente | F16: Presente | G16: Ausente | H16: Presente | I16: Presente | J16: =COUNTIF(D16:I16,"Presente")+COUNTIF(D16:I16,"Tardanza") -> 4 | K16: =COUNTIF(D16:I16,"Ausente") -> 2 | L16: =IFERROR(J16/6,0) -> 0.66666667
A17: 12 | J17: =COUNTIF(D17:I17,"Presente")+COUNTIF(D17:I17,"Tardanza") -> 0 | K17: =COUNTIF(D17:I17,"Ausente") -> 0 | L17: =IFERROR(J17/6,0) -> 0
A18: 13 | J18: =COUNTIF(D18:I18,"Presente")+COUNTIF(D18:I18,"Tardanza") -> 0 | K18: =COUNTIF(D18:I18,"Ausente") -> 0 | L18: =IFERROR(J18/6,0) -> 0
A19: 14 | J19: =COUNTIF(D19:I19,"Presente")+COUNTIF(D19:I19,"Tardanza") -> 0 | K19: =COUNTIF(D19:I19,"Ausente") -> 0 | L19: =IFERROR(J19/6,0) -> 0
A20: 15 | J20: =COUNTIF(D20:I20,"Presente")+COUNTIF(D20:I20,"Tardanza") -> 0 | K20: =COUNTIF(D20:I20,"Ausente") -> 0 | L20: =IFERROR(J20/6,0) -> 0
A21: 16 | J21: =COUNTIF(D21:I21,"Presente")+COUNTIF(D21:I21,"Tardanza") -> 0 | K21: =COUNTIF(D21:I21,"Ausente") -> 0 | L21: =IFERROR(J21/6,0) -> 0
A22: 17 | J22: =COUNTIF(D22:I22,"Presente")+COUNTIF(D22:I22,"Tardanza") -> 0 | K22: =COUNTIF(D22:I22,"Ausente") -> 0 | L22: =IFERROR(J22/6,0) -> 0
A23: 18 | J23: =COUNTIF(D23:I23,"Presente")+COUNTIF(D23:I23,"Tardanza") -> 0 | K23: =COUNTIF(D23:I23,"Ausente") -> 0 | L23: =IFERROR(J23/6,0) -> 0
A24: 19 | J24: =COUNTIF(D24:I24,"Presente")+COUNTIF(D24:I24,"Tardanza") -> 0 | K24: =COUNTIF(D24:I24,"Ausente") -> 0 | L24: =IFERROR(J24/6,0) -> 0
A25: 20 | J25: =COUNTIF(D25:I25,"Presente")+COUNTIF(D25:I25,"Tardanza") -> 0 | K25: =COUNTIF(D25:I25,"Ausente") -> 0 | L25: =IFERROR(J25/6,0) -> 0
A26: 21 | J26: =COUNTIF(D26:I26,"Presente")+COUNTIF(D26:I26,"Tardanza") -> 0 | K26: =COUNTIF(D26:I26,"Ausente") -> 0 | L26: =IFERROR(J26/6,0) -> 0
A27: 22 | J27: =COUNTIF(D27:I27,"Presente")+COUNTIF(D27:I27,"Tardanza") -> 0 | K27: =COUNTIF(D27:I27,"Ausente") -> 0 | L27: =IFERROR(J27/6,0) -> 0
A28: 23 | J28: =COUNTIF(D28:I28,"Presente")+COUNTIF(D28:I28,"Tardanza") -> 0 | K28: =COUNTIF(D28:I28,"Ausente") -> 0 | L28: =IFERROR(J28/6,0) -> 0
... A35: 30 | J35: =COUNTIF(D35:I35,"Presente")+COUNTIF(D35:I35,"Tardanza") -> 0 | K35: =COUNTIF(D35:I35,"Ausente") -> 0 | L35: =IFERROR(J35/6,0) -> 0
A37: GRUPO 2 — Martes y Jueves
A38: # | B38: Fecha | C38: Sesión N° | D38: Pinilla, Alexis | E38: Lorenzetti, Axel | F38: Leal, Benjamín | G38: Calascibetta, Felipe | H38: Mottin, Francisco | I38: Cappelletti, Sofía | J38: Presentes | K38: Ausentes | L38: % Asist.
A39: 1 | B39: 46189 | C39: 1 | D39: Presente | E39: Presente | F39: Ausente | G39: Presente | H39: Presente | I39: Presente | J39: =COUNTIF(D39:I39,"Presente")+COUNTIF(D39:I39,"Tardanza") -> 5 | K39: =COUNTIF(D39:I39,"Ausente") -> 1 | L39: =IFERROR(J39/6,0) -> 0.83333333
A40: 2 | B40: 46191 | C40: 2 | D40: Presente | E40: Tardanza | F40: Presente | G40: Ausente | H40: Presente | I40: Presente | J40: =COUNTIF(D40:I40,"Presente")+COUNTIF(D40:I40,"Tardanza") -> 5 | K40: =COUNTIF(D40:I40,"Ausente") -> 1 | L40: =IFERROR(J40/6,0) -> 0.83333333
A41: 3 | B41: 46196 | C41: 3 | D41: Presente | E41: Presente | F41: Presente | G41: Presente | H41: Presente | I41: Presente | J41: =COUNTIF(D41:I41,"Presente")+COUNTIF(D41:I41,"Tardanza") -> 6 | K41: =COUNTIF(D41:I41,"Ausente") -> 0 | L41: =IFERROR(J41/6,0) -> 1
A42: 4 | B42: 46198 | C42: 4 | D42: Presente | E42: Presente | F42: Presente | G42: Presente | H42: Presente | I42: Presente | J42: =COUNTIF(D42:I42,"Presente")+COUNTIF(D42:I42,"Tardanza") -> 6 | K42: =COUNTIF(D42:I42,"Ausente") -> 0 | L42: =IFERROR(J42/6,0) -> 1
A43: 5 | B43: 46203 | C43: 5 | D43: Presente | E43: Presente | F43: Presente | G43: Presente | H43: Presente | I43: Presente | J43: =COUNTIF(D43:I43,"Presente")+COUNTIF(D43:I43,"Tardanza") -> 6 | K43: =COUNTIF(D43:I43,"Ausente") -> 0 | L43: =IFERROR(J43/6,0) -> 1
A44: 6 | B44: 46205 | C44: 6 | D44: Presente | E44: Ausente | F44: Presente | G44: Presente | H44: Presente | I44: Presente | J44: =COUNTIF(D44:I44,"Presente")+COUNTIF(D44:I44,"Tardanza") -> 5 | K44: =COUNTIF(D44:I44,"Ausente") -> 1 | L44: =IFERROR(J44/6,0) -> 0.83333333
A45: 7 | B45: 46210 | C45: 7 | D45: Presente | E45: Presente | F45: Justificado | G45: Presente | H45: Presente | I45: Ausente | J45: =COUNTIF(D45:I45,"Presente")+COUNTIF(D45:I45,"Tardanza") -> 4 | K45: =COUNTIF(D45:I45,"Ausente") -> 1 | L45: =IFERROR(J45/6,0) -> 0.66666667
A46: 8 | B46: 46217 | C46: 8 | D46: Ausente | E46: Presente | F46: Presente | G46: Ausente | H46: Presente | I46: Presente | J46: =COUNTIF(D46:I46,"Presente")+COUNTIF(D46:I46,"Tardanza") -> 4 | K46: =COUNTIF(D46:I46,"Ausente") -> 2 | L46: =IFERROR(J46/6,0) -> 0.66666667
A47: 9 | B47: 46219 | C47: 9 | D47: Presente | E47: Presente | F47: Presente | G47: Ausente | H47: Presente | I47: Ausente | J47: =COUNTIF(D47:I47,"Presente")+COUNTIF(D47:I47,"Tardanza") -> 4 | K47: =COUNTIF(D47:I47,"Ausente") -> 2 | L47: =IFERROR(J47/6,0) -> 0.66666667
A48: 10 | B48: 46245 | C48: 10 | D48: Presente | E48: Presente | F48: Presente | G48: Presente | H48: Presente | I48: Presente | J48: =COUNTIF(D48:I48,"Presente")+COUNTIF(D48:I48,"Tardanza") -> 6 | K48: =COUNTIF(D48:I48,"Ausente") -> 0 | L48: =IFERROR(J48/6,0) -> 1
...

Sheet 🏫 TERRITORIO
A1: 🏫 REGISTRO DE VISITAS A TERRITORIO
A2: Desbloqueos, cambio de pilas y diagnóstico en escuelas — Región 1
A4: # | B4: N° OT | C4: Fecha | D4: Escuela | E4: CUE | F4: Distrito | G4: N° de Serie | H4: Estado Inicial | I4: Acción | J4: Grupo | K4: Responsable | L4: Estado Final | M4: Observaciones | P4: Responsables (no borrar)
A5: =IF(G5<>"",ROW()-4,"") -> 1 | B5: =IF(G5<>"","OT-2026-"&TEXT(ROW()-4,"000"),"") -> OT-2026-001 | C5: 46210 | D5: LA PLATA | ESCUELA DE EDUCACIÓN PRIMARIA N° 2 PROF. ANDRES FERREYRA (CUE: 60881800) | E5: =IFERROR(VLOOKUP(D5,'🗂️ DATA_ESCUELAS'!$A:$D,2,0),"") -> 60881800 | F5: =IFERROR(VLOOKUP(D5,'🗂️ DATA_ESCUELAS'!$A:$D,3,0),"") -> LA PLATA | G5: SZSES10IS232513800 | H5: Bloqueada | I5: Desbloqueo + Cambio de Pila, Actualización de SO | J5: Grupo 2 | K5: Pinilla, Alexis | L5: Finalizada OK | M5: tiene roto el boton de encendido y en una esquina tiene oscura la pantalla | P5: ='🏅 RANKING'!B4 -> Kovach, Ludmila
A6: =IF(G6<>"",ROW()-4,"") -> 2 | B6: =IF(G6<>"","OT-2026-"&TEXT(ROW()-4,"000"),"") -> OT-2026-002 | C6: 46210 | D6: LA PLATA | ESCUELA DE EDUCACIÓN PRIMARIA N° 2 PROF. ANDRES FERREYRA (CUE: 60881800) | E6: =IFERROR(VLOOKUP(D6,'🗂️ DATA_ESCUELAS'!$A:$D,2,0),"") -> 60881800 | F6: =IFERROR(VLOOKUP(D6,'🗂️ DATA_ESCUELAS'!$A:$D,3,0),"") -> LA PLATA | G6: SZSES10IS232301340 | H6: Bloqueada | I6: Desbloqueo + Cambio de Pila, Actualización de SO | J6: Grupo 2 | K6: Lorenzetti, Axel | L6: Finalizada OK | P6: ='🏅 RANKING'!B5 -> Terraza, Brian
A7: =IF(G7<>"",ROW()-4,"") -> 3 | B7: =IF(G7<>"","OT-2026-"&TEXT(ROW()-4,"000"),"") -> OT-2026-003 | C7: 46210 | D7: LA PLATA | ESCUELA DE EDUCACIÓN PRIMARIA N° 2 PROF. ANDRES FERREYRA (CUE: 60881800) | E7: =IFERROR(VLOOKUP(D7,'🗂️ DATA_ESCUELAS'!$A:$D,2,0),"") -> 60881800 | F7: =IFERROR(VLOOKUP(D7,'🗂️ DATA_ESCUELAS'!$A:$D,3,0),"") -> LA PLATA | G7: SZSES10IS2323024565 | H7: Diagnosticada | I7: Otro | J7: Grupo 2 | K7: Mottin, Francisco | L7: Derivada | M7: cambiar pantalla | P7: ='🏅 RANKING'!B6 -> Pedrozo, Lorena
A8: =IF(G8<>"",ROW()-4,"") -> 4 | B8: =IF(G8<>"","OT-2026-"&TEXT(ROW()-4,"000"),"") -> OT-2026-004 | C8: 46210 | D8: LA PLATA | ESCUELA DE EDUCACIÓN PRIMARIA N° 2 PROF. ANDRES FERREYRA (CUE: 60881800) | E8: =IFERROR(VLOOKUP(D8,'🗂️ DATA_ESCUELAS'!$A:$D,2,0),"") -> 60881800 | F8: =IFERROR(VLOOKUP(D8,'🗂️ DATA_ESCUELAS'!$A:$D,3,0),"") -> LA PLATA | G8: EDU8126576 | H8: Diagnosticada | I8: Otro | J8: Grupo 2 | K8: Mottin, Francisco | L8: Derivada | M8: queda la pantalla en blanco | P8: ='🏅 RANKING'!B7 -> Cáceres, Santiago
A9: =IF(G9<>"",ROW()-4,"") -> 5 | B9: =IF(G9<>"","OT-2026-"&TEXT(ROW()-4,"000"),"") -> OT-2026-005 | C9: 46210 | D9: LA PLATA | ESCUELA DE EDUCACIÓN PRIMARIA N° 2 PROF. ANDRES FERREYRA (CUE: 60881800) | E9: =IFERROR(VLOOKUP(D9,'🗂️ DATA_ESCUELAS'!$A:$D,2,0),"") -> 60881800 | F9: =IFERROR(VLOOKUP(D9,'🗂️ DATA_ESCUELAS'!$A:$D,3,0),"") -> LA PLATA | G9: SZSES10IS232513444 | H9: Diagnosticada | I9: Otro | J9: Grupo 2 | K9: Mottin, Francisco | L9: Derivada | M9: cambiar pantalla | P9: ='🏅 RANKING'!B8 -> Aguilera, Thiago
A10: =IF(G10<>"",ROW()-4,"") -> 6 | B10: =IF(G10<>"","OT-2026-"&TEXT(ROW()-4,"000"),"") -> OT-2026-006 | C10: 46210 | D10: LA PLATA | ESCUELA DE EDUCACIÓN PRIMARIA N° 2 PROF. ANDRES FERREYRA (CUE: 60881800) | E10: =IFERROR(VLOOKUP(D10,'🗂️ DATA_ESCUELAS'!$A:$D,2,0),"") -> 60881800 | F10: =IFERROR(VLOOKUP(D10,'🗂️ DATA_ESCUELAS'!$A:$D,3,0),"") -> LA PLATA | G10: S/N | H10: SO Instalado | I10: Actualización de SO | J10: Grupo 2 | K10: Mottin, Francisco | L10: Finalizada OK | M10: en la esquina derecha de arriba de la pantalla esta oscuro | P10: ='🏅 RANKING'!B9 -> Simonetti, Tomás
A11: =IF(G12<>"",ROW()-4,"") -> 7 | B11: =IF(G12<>"","OT-2026-"&TEXT(ROW()-4,"000"),"") -> OT-2026-007 | C11: 46210 | D11: LA PLATA | ESCUELA DE EDUCACIÓN PRIMARIA N° 2 PROF. ANDRES FERREYRA (CUE: 60881800) | E11: =IFERROR(VLOOKUP(D11,'🗂️ DATA_ESCUELAS'!$A:$D,2,0),"") -> 60881800 | F11: =IFERROR(VLOOKUP(D11,'🗂️ DATA_ESCUELAS'!$A:$D,3,0),"") -> LA PLATA | G11: SZSES10IS232513687 | H11: Bloqueada | I11: Desbloqueo, Actualización de SO | J11: Grupo 2 | K11: Silvio Ridolfi (FED) | L11: Finalizada OK | P11: ='🏅 RANKING'!B10 -> Pinilla, Alexis
A12: =IF(G13<>"",ROW()-4,"") -> 8 | B12: =IF(G13<>"","OT-2026-"&TEXT(ROW()-4,"000"),"") -> OT-2026-008 | C12: 46210 | D12: LA PLATA | ESCUELA DE EDUCACIÓN PRIMARIA N° 2 PROF. ANDRES FERREYRA (CUE: 60881800) | E12: =IFERROR(VLOOKUP(D12,'🗂️ DATA_ESCUELAS'!$A:$D,2,0),"") -> 60881800 | F12: =IFERROR(VLOOKUP(D12,'🗂️ DATA_ESCUELAS'!$A:$D,3,0),"") -> LA PLATA | G12: EDU8125658 | H12: SO Instalado | I12: Actualización de SO | J12: Grupo 2 | K12: Mottin, Francisco | L12: Finalizada OK | M12: le falta la tecla f9 | P12: ='🏅 RANKING'!B11 -> Lorenzetti, Axel
A13: =IF(G13<>"",ROW()-4,"") -> 9 | B13: =IF(G13<>"","OT-2026-"&TEXT(ROW()-4,"000"),"") -> OT-2026-009 | C13: 46210 | D13: LA PLATA | ESCUELA DE EDUCACIÓN PRIMARIA N° 2 PROF. ANDRES FERREYRA (CUE: 60881800) | E13: =IFERROR(VLOOKUP(D13,'🗂️ DATA_ESCUELAS'!$A:$D,2,0),"") -> 60881800 | F13: =IFERROR(VLOOKUP(D13,'🗂️ DATA_ESCUELAS'!$A:$D,3,0),"") -> LA PLATA | G13: SZSES10IS2323301344 | H13: Bloqueada | I13: Desbloqueo | J13: Grupo 2 | K13: Lorenzetti, Axel | L13: Finalizada OK | M13: Se cambia botón de encendido | P13: ='🏅 RANKING'!B12 -> Leal, Benjamín
A14: =IF(G14<>"",ROW()-4,"") -> 10 | B14: =IF(G14<>"","OT-2026-"&TEXT(ROW()-4,"000"),"") -> OT-2026-010 | C14: 46210 | D14: LA PLATA | ESCUELA DE EDUCACIÓN PRIMARIA N° 2 PROF. ANDRES FERREYRA (CUE: 60881800) | E14: =IFERROR(VLOOKUP(D14,'🗂️ DATA_ESCUELAS'!$A:$D,2,0),"") -> 60881800 | F14: =IFERROR(VLOOKUP(D14,'🗂️ DATA_ESCUELAS'!$A:$D,3,0),"") -> LA PLATA | G14: EDU8123076 | H14: SO Instalado | I14: Actualización de SO | J14: Grupo 2 | K14: Mottin, Francisco | L14: Finalizada OK | P14: ='🏅 RANKING'!B13 -> Calascibetta, Felipe
A15: =IF(G15<>"",ROW()-4,"") -> 11 | B15: =IF(G15<>"","OT-2026-"&TEXT(ROW()-4,"000"),"") -> OT-2026-011 | C15: 46210 | D15: LA PLATA | ESCUELA DE EDUCACIÓN PRIMARIA N° 2 PROF. ANDRES FERREYRA (CUE: 60881800) | E15: =IFERROR(VLOOKUP(D15,'🗂️ DATA_ESCUELAS'!$A:$D,2,0),"") -> 60881800 | F15: =IFERROR(VLOOKUP(D15,'🗂️ DATA_ESCUELAS'!$A:$D,3,0),"") -> LA PLATA | G15: SZSES10IS232513787 | H15: Bloqueada | I15: Desbloqueo | J15: Grupo 2 | K15: Pinilla, Alexis | L15: Finalizada OK | P15: ='🏅 RANKING'!B14 -> Mottin, Francisco
A16: =IF(G16<>"",ROW()-4,"") -> 12 | B16: =IF(G16<>"","OT-2026-"&TEXT(ROW()-4,"000"),"") -> OT-2026-012 | C16: 46210 | D16: LA PLATA | ESCUELA DE EDUCACIÓN PRIMARIA N° 2 PROF. ANDRES FERREYRA (CUE: 60881800) | E16: =IFERROR(VLOOKUP(D16,'🗂️ DATA_ESCUELAS'!$A:$D,2,0),"") -> 60881800 | F16: =IFERROR(VLOOKUP(D16,'🗂️ DATA_ESCUELAS'!$A:$D,3,0),"") -> LA PLATA | G16: S/N | H16: Bloqueada | I16: Desbloqueo, Actualización de SO | J16: Grupo 2 | K16: Silvio Ridolfi (FED) | L16: Finalizada OK | P16: ='🏅 RANKING'!B15 -> Cappelletti, Sofía
A17: =IF(G17<>"",ROW()-4,"") -> 13 | B17: =IF(G17<>"","OT-2026-"&TEXT(ROW()-4,"000"),"") -> OT-2026-013 | C17: 46210 | D17: LA PLATA | ESCUELA DE EDUCACIÓN PRIMARIA N° 2 PROF. ANDRES FERREYRA (CUE: 60881800) | E17: =IFERROR(VLOOKUP(D17,'🗂️ DATA_ESCUELAS'!$A:$D,2,0),"") -> 60881800 | F17: =IFERROR(VLOOKUP(D17,'🗂️ DATA_ESCUELAS'!$A:$D,3,0),"") -> LA PLATA | G17: SZSES10IS232513784 | H17: Bloqueada | I17: Desbloqueo, Actualización de SO | J17: Grupo 2 | K17: Silvio Ridolfi (FED) | L17: Finalizada OK | P17: Silvio Ridolfi (FED)
A18: =IF(G18<>"",ROW()-4,"") -> 14 | B18: =IF(G18<>"","OT-2026-"&TEXT(ROW()-4,"000"),"") -> OT-2026-014 | C18: 46210 | D18: LA PLATA | ESCUELA DE EDUCACIÓN PRIMARIA N° 2 PROF. ANDRES FERREYRA (CUE: 60881800) | E18: =IFERROR(VLOOKUP(D18,'🗂️ DATA_ESCUELAS'!$A:$D,2,0),"") -> 60881800 | F18: =IFERROR(VLOOKUP(D18,'🗂️ DATA_ESCUELAS'!$A:$D,3,0),"") -> LA PLATA | G18: EDU8125735 | H18: Bloqueada | I18: Desbloqueo | J18: Grupo 2 | K18: Silvio Ridolfi (FED) | L18: Derivada | M18: tiene la pantalla rota
A19: =IF(G19<>"",ROW()-4,"") -> 15 | B19: =IF(G19<>"","OT-2026-"&TEXT(ROW()-4,"000"),"") -> OT-2026-015 | C19: 46210 | D19: LA PLATA | ESCUELA DE EDUCACIÓN PRIMARIA N° 2 PROF. ANDRES FERREYRA (CUE: 60881800) | E19: =IFERROR(VLOOKUP(D19,'🗂️ DATA_ESCUELAS'!$A:$D,2,0),"") -> 60881800 | F19: =IFERROR(VLOOKUP(D19,'🗂️ DATA_ESCUELAS'!$A:$D,3,0),"") -> LA PLATA | G19: S/N | H19: Bloqueada | I19: Desbloqueo | J19: Grupo 2 | K19: Mottin, Francisco | L19: Finalizada OK | M19: No funciona teclado
A20: =IF(G20<>"",ROW()-4,"") -> 16 | B20: =IF(G20<>"","OT-2026-"&TEXT(ROW()-4,"000"),"") -> OT-2026-016 | C20: 46210 | D20: LA PLATA | ESCUELA DE EDUCACIÓN PRIMARIA N° 2 PROF. ANDRES FERREYRA (CUE: 60881800) | E20: =IFERROR(VLOOKUP(D20,'🗂️ DATA_ESCUELAS'!$A:$D,2,0),"") -> 60881800 | F20: =IFERROR(VLOOKUP(D20,'🗂️ DATA_ESCUELAS'!$A:$D,3,0),"") -> LA PLATA | G20: NET 12 | H20: Desbloqueada | I20: Otro | K20: Silvio Ridolfi (FED) | L20: Derivada | M20: PANTALLA ROTA
A21: =IF(G21<>"",ROW()-4,"") -> 17 | B21: =IF(G21<>"","OT-2026-"&TEXT(ROW()-4,"000"),"") -> OT-2026-017 | C21: 46210 | D21: LA PLATA | ESCUELA DE EDUCACIÓN PRIMARIA N° 2 PROF. ANDRES FERREYRA (CUE: 60881800) | E21: =IFERROR(VLOOKUP(D21,'🗂️ DATA_ESCUELAS'!$A:$D,2,0),"") -> 60881800 | F21: =IFERROR(VLOOKUP(D21,'🗂️ DATA_ESCUELAS'!$A:$D,3,0),"") -> LA PLATA | G21: NET 16 | H21: Desbloqueada | I21: Otro | K21: Silvio Ridolfi (FED) | L21: Finalizada OK
A22: =IF(G22<>"",ROW()-4,"") -> 18 | B22: =IF(G22<>"","OT-2026-"&TEXT(ROW()-4,"000"),"") -> OT-2026-018 | C22: 46210 | D22: LA PLATA | ESCUELA DE EDUCACIÓN PRIMARIA N° 2 PROF. ANDRES FERREYRA (CUE: 60881800) | E22: =IFERROR(VLOOKUP(D22,'🗂️ DATA_ESCUELAS'!$A:$D,2,0),"") -> 60881800 | F22: =IFERROR(VLOOKUP(D22,'🗂️ DATA_ESCUELAS'!$A:$D,3,0),"") -> LA PLATA | G22: NET 18 | H22: Desbloqueada | I22: Otro | K22: Silvio Ridolfi (FED) | L22: Finalizada OK
A23: =IF(G23<>"",ROW()-4,"") -> 19 | B23: =IF(G23<>"","OT-2026-"&TEXT(ROW()-4,"000"),"") -> OT-2026-019 | C23: 46210 | D23: LA PLATA | ESCUELA DE EDUCACIÓN PRIMARIA N° 2 PROF. ANDRES FERREYRA (CUE: 60881800) | E23: =IFERROR(VLOOKUP(D23,'🗂️ DATA_ESCUELAS'!$A:$D,2,0),"") -> 60881800 | F23: =IFERROR(VLOOKUP(D23,'🗂️ DATA_ESCUELAS'!$A:$D,3,0),"") -> LA PLATA | G23: NET 8 | H23: Desbloqueada | I23: Otro | K23: Silvio Ridolfi (FED) | L23: Finalizada OK
A24: =IF(G24<>"",ROW()-4,"") -> 20 | B24: =IF(G24<>"","OT-2026-"&TEXT(ROW()-4,"000"),"") -> OT-2026-020 | C24: 46210 | D24: LA PLATA | ESCUELA DE EDUCACIÓN PRIMARIA N° 2 PROF. ANDRES FERREYRA (CUE: 60881800) | E24: =IFERROR(VLOOKUP(D24,'🗂️ DATA_ESCUELAS'!$A:$D,2,0),"") -> 60881800 | F24: =IFERROR(VLOOKUP(D24,'🗂️ DATA_ESCUELAS'!$A:$D,3,0),"") -> LA PLATA | G24: NET 2 | H24: Desbloqueada | I24: Otro | K24: Silvio Ridolfi (FED) | L24: Derivada | M24: Sin botón de encendido
A25: =IF(G25<>"",ROW()-4,"") | B25: =IF(G25<>"","OT-2026-"&TEXT(ROW()-4,"000"),"") | E25: =IFERROR(VLOOKUP(D25,'🗂️ DATA_ESCUELAS'!$A:$D,2,0),"") | F25: =IFERROR(VLOOKUP(D25,'🗂️ DATA_ESCUELAS'!$A:$D,3,0),"")
A26: =IF(G26<>"",ROW()-4,"") | B26: =IF(G26<>"","OT-2026-"&TEXT(ROW()-4,"000"),"") | E26: =IFERROR(VLOOKUP(D26,'🗂️ DATA_ESCUELAS'!$A:$D,2,0),"") | F26: =IFERROR(VLOOKUP(D26,'🗂️ DATA_ESCUELAS'!$A:$D,3,0),"")
A27: =IF(G27<>"",ROW()-4,"") | B27: =IF(G27<>"","OT-2026-"&TEXT(ROW()-4,"000"),"") | E27: =IFERROR(VLOOKUP(D27,'🗂️ DATA_ESCUELAS'!$A:$D,2,0),"") | F27: =IFERROR(VLOOKUP(D27,'🗂️ DATA_ESCUELAS'!$A:$D,3,0),"")
A28: =IF(G28<>"",ROW()-4,"") | B28: =IF(G28<>"","OT-2026-"&TEXT(ROW()-4,"000"),"") | E28: =IFERROR(VLOOKUP(D28,'🗂️ DATA_ESCUELAS'!$A:$D,2,0),"") | F28: =IFERROR(VLOOKUP(D28,'🗂️ DATA_ESCUELAS'!$A:$D,3,0),"")
A29: =IF(G29<>"",ROW()-4,"") | B29: =IF(G29<>"","OT-2026-"&TEXT(ROW()-4,"000"),"") | E29: =IFERROR(VLOOKUP(D29,'🗂️ DATA_ESCUELAS'!$A:$D,2,0),"") | F29: =IFERROR(VLOOKUP(D29,'🗂️ DATA_ESCUELAS'!$A:$D,3,0),"")
A30: =IF(G30<>"",ROW()-4,"") | B30: =IF(G30<>"","OT-2026-"&TEXT(ROW()-4,"000"),"") | E30: =IFERROR(VLOOKUP(D30,'🗂️ DATA_ESCUELAS'!$A:$D,2,0),"") | F30: =IFERROR(VLOOKUP(D30,'🗂️ DATA_ESCUELAS'!$A:$D,3,0),"")
A31: =IF(G31<>"",ROW()-4,"") | B31: =IF(G31<>"","OT-2026-"&TEXT(ROW()-4,"000"),"") | E31: =IFERROR(VLOOKUP(D31,'🗂️ DATA_ESCUELAS'!$A:$D,2,0),"") | F31: =IFERROR(VLOOKUP(D31,'🗂️ DATA_ESCUELAS'!$A:$D,3,0),"")
A32: =IF(G32<>"",ROW()-4,"") | B32: =IF(G32<>"","OT-2026-"&TEXT(ROW()-4,"000"),"") | E32: =IFERROR(VLOOKUP(D32,'🗂️ DATA_ESCUELAS'!$A:$D,2,0),"") | F32: =IFERROR(VLOOKUP(D32,'🗂️ DATA_ESCUELAS'!$A:$D,3,0),"")
A33: =IF(G33<>"",ROW()-4,"") | B33: =IF(G33<>"","OT-2026-"&TEXT(ROW()-4,"000"),"") | E33: =IFERROR(VLOOKUP(D33,'🗂️ DATA_ESCUELAS'!$A:$D,2,0),"") | F33: =IFERROR(VLOOKUP(D33,'🗂️ DATA_ESCUELAS'!$A:$D,3,0),"")
A34: =IF(G34<>"",ROW()-4,"") | B34: =IF(G34<>"","OT-2026-"&TEXT(ROW()-4,"000"),"") | E34: =IFERROR(VLOOKUP(D34,'🗂️ DATA_ESCUELAS'!$A:$D,2,0),"") | F34: =IFERROR(VLOOKUP(D34,'🗂️ DATA_ESCUELAS'!$A:$D,3,0),"")
A35: =IF(G35<>"",ROW()-4,"") | B35: =IF(G35<>"","OT-2026-"&TEXT(ROW()-4,"000"),"") | E35: =IFERROR(VLOOKUP(D35,'🗂️ DATA_ESCUELAS'!$A:$D,2,0),"") | F35: =IFERROR(VLOOKUP(D35,'🗂️ DATA_ESCUELAS'!$A:$D,3,0),"")
A36: =IF(G36<>"",ROW()-4,"") | B36: =IF(G36<>"","OT-2026-"&TEXT(ROW()-4,"000"),"") | E36: =IFERROR(VLOOKUP(D36,'🗂️ DATA_ESCUELAS'!$A:$D,2,0),"") | F36: =IFERROR(VLOOKUP(D36,'🗂️ DATA_ESCUELAS'!$A:$D,3,0),"")
... A253: =IF(G253<>"",ROW()-4,"") | B253: =IF(G253<>"","OT-2026-"&TEXT(ROW()-4,"000"),"") | E253: =IFERROR(VLOOKUP(D253,'🗂️ DATA_ESCUELAS'!$A:$D,2,0),"") | F253: =IFERROR(VLOOKUP(D253,'🗂️ DATA_ESCUELAS'!$A:$D,3,0),"")
A254: =IF(G254<>"",ROW()-4,"") | B254: =IF(G254<>"","OT-TER-2026-"&TEXT(ROW()-4,"000"),"") | E254: =IFERROR(VLOOKUP(D254,'🗂️ DATA_ESCUELAS'!$A:$D,2,0),"") | F254: =IFERROR(VLOOKUP(D254,'🗂️ DATA_ESCUELAS'!$A:$D,3,0),"")
A255: =IF(G255<>"",ROW()-4,"") | B255: =IF(G255<>"","OT-TER-2026-"&TEXT(ROW()-4,"000"),"") | E255: =IFERROR(VLOOKUP(D255,'🗂️ DATA_ESCUELAS'!$A:$D,2,0),"") | F255: =IFERROR(VLOOKUP(D255,'🗂️ DATA_ESCUELAS'!$A:$D,3,0),"")
A256: =IF(G256<>"",ROW()-4,"") | B256: =IF(G256<>"","OT-TER-2026-"&TEXT(ROW()-4,"000"),"") | E256: =IFERROR(VLOOKUP(D256,'🗂️ DATA_ESCUELAS'!$A:$D,2,0),"") | F256: =IFERROR(VLOOKUP(D256,'🗂️ DATA_ESCUELAS'!$A:$D,3,0),"")
A257: =IF(G257<>"",ROW()-4,"") | B257: =IF(G257<>"","OT-TER-2026-"&TEXT(ROW()-4,"000"),"") | E257: =IFERROR(VLOOKUP(D257,'🗂️ DATA_ESCUELAS'!$A:$D,2,0),"") | F257: =IFERROR(VLOOKUP(D257,'🗂️ DATA_ESCUELAS'!$A:$D,3,0),"")
...

Sheet 🔧 OT
A1: 🔧 ÓRDENES DE TRABAJO
A2: Registro completo de intervenciones | OT-2026-XXX
A3: # | B3: N° OT | C3: Fecha | D3: Equipo (N° Serie) | E3: Formato | F3: Generación | G3: Grupo | H3: Responsable | I3: Estado Inicial | J3: Hs. Est. | K3: Hs. Real | L3: Historial de Intervenciones | M3: Observaciones | N3: Estado Final
A4: 1 | B4: =IF(D4<>"","OT-2026-"&TEXT(ROW()-3,"000"),"") -> OT-2026-001 | C4: 46189 | D4: AA4163047472 | E4: =IFERROR(__xludf.DUMMYFUNCTION("IF(D4="""", """", IF(REGEXMATCH(TO_TEXT(D4), ""^(AA\d{10}|EDU\d{7}|\d+|SZSES10IS\d{9})$""), ""✅"", ""⚠️""))"),"✅") -> ✅ | F4: G4 | G4: Grupo 2 | H4: Lorenzetti, Axel | I4: =IFERROR(__xludf.DUMMYFUNCTION("IF(D4="""", """", IFERROR(VLOOKUP(TO_TEXT(D4), '💻 EQUIPOS'!B:H, 7, 0), """"))"),"Bloqueada") -> Bloqueada | J4: 60m | K4: 43m | L4: se desbloqueo | M4: esta roto el conector del teclado,disco actual es de 160,se cambia por uno de 320,queda para reutilizar un disco de 160,funciona mal la pantalla | N4: Finalizada OK
A5: 2 | B5: =IF(D5<>"","OT-2026-"&TEXT(ROW()-3,"000"),"") -> OT-2026-002 | C5: 46189 | D5: AA1183076736 | E5: =IFERROR(__xludf.DUMMYFUNCTION("IF(D5="""", """", IF(REGEXMATCH(TO_TEXT(D5), ""^(AA\d{10}|EDU\d{7}|\d+|SZSES10IS\d{9})$""), ""✅"", ""⚠️""))"),"✅") -> ✅ | F5: G4 | G5: Grupo 2 | H5: Lorenzetti, Axel | I5: =IFERROR(__xludf.DUMMYFUNCTION("IF(D5="""", """", IFERROR(VLOOKUP(TO_TEXT(D5), '💻 EQUIPOS'!B:H, 7, 0), """"))"),"Bloqueada") -> Bloqueada | J5: 45m | K5: 55m | L5: se desbloqueo | M5: se desbloqueo,falta testear ya se instaló el SO, no le andan las teclas X,C y V | N5: Finalizada OK
A6: 3 | B6: =IF(D6<>"","OT-2026-"&TEXT(ROW()-3,"000"),"") -> OT-2026-003 | C6: 46190 | D6: AA3313139031 | E6: =IFERROR(__xludf.DUMMYFUNCTION("IF(D6="""", """", IF(REGEXMATCH(TO_TEXT(D6), ""^(AA\d{10}|EDU\d{7}|\d+|SZSES10IS\d{9})$""), ""✅"", ""⚠️""))"),"✅") -> ✅ | F6: G4 | G6: Grupo 1 | H6: Terraza, Brian | I6: =IFERROR(__xludf.DUMMYFUNCTION("IF(D6="""", """", IFERROR(VLOOKUP(TO_TEXT(D6), '💻 EQUIPOS'!B:H, 7, 0), """"))"),"Bloqueada") -> Bloqueada | J6: 60m | K6: 45m | L6: se desbloqueo | M6: se desbloqueo,esta rota la pantalla, | N6: Finalizada OK
A7: 4 | B7: =IF(D7<>"","OT-2026-"&TEXT(ROW()-3,"000"),"") -> OT-2026-004 | C7: 46190 | D7: AA1313665703 | E7: =IFERROR(__xludf.DUMMYFUNCTION("IF(D7="""", """", IF(REGEXMATCH(TO_TEXT(D7), ""^(AA\d{10}|EDU\d{7}|\d+|SZSES10IS\d{9})$""), ""✅"", ""⚠️""))"),"✅") -> ✅ | F7: G4 | G7: Grupo 1 | H7: Terraza, Brian | I7: =IFERROR(__xludf.DUMMYFUNCTION("IF(D7="""", """", IFERROR(VLOOKUP(TO_TEXT(D7), '💻 EQUIPOS'!B:H, 7, 0), """"))"),"Bloqueada") -> Bloqueada | J7: 40m | K7: 55m | L7: se desbloqueo | M7: Pulsador de botón encendido está roto, no tiene bateria | N7: Derivada
A8: 5 | B8: =IF(D8<>"","OT-2026-"&TEXT(ROW()-3,"000"),"") -> OT-2026-005 | C8: 46191 | D8: AA1183077623 | E8: =IFERROR(__xludf.DUMMYFUNCTION("IF(D8="""", """", IF(REGEXMATCH(TO_TEXT(D8), ""^(AA\d{10}|EDU\d{7}|\d+|SZSES10IS\d{9})$""), ""✅"", ""⚠️""))"),"✅") -> ✅ | F8: G4 | G8: Grupo 2 | H8: Leal, Benjamín | I8: =IFERROR(__xludf.DUMMYFUNCTION("IF(D8="""", """", IFERROR(VLOOKUP(TO_TEXT(D8), '💻 EQUIPOS'!B:H, 7, 0), """"))"),"Bloqueada") -> Bloqueada | J8: 60m | K8: 50m | L8: se desbloqueo | M8: se desbloqueo, enciende pero no tiene pila, se le instalo so, | N8: Finalizada OK
A9: 6 | B9: =IF(D9<>"","OT-2026-"&TEXT(ROW()-3,"000"),"") -> OT-2026-006 | C9: 46191 | D9: AA6053091118 | E9: =IFERROR(__xludf.DUMMYFUNCTION("IF(D9="""", """", IF(REGEXMATCH(TO_TEXT(D9), ""^(AA\d{10}|EDU\d{7}|\d+|SZSES10IS\d{9})$""), ""✅"", ""⚠️""))"),"✅") -> ✅ | F9: G4 | G9: Grupo 2 | H9: Lorenzetti, Axel | I9: =IFERROR(__xludf.DUMMYFUNCTION("IF(D9="""", """", IFERROR(VLOOKUP(TO_TEXT(D9), '💻 EQUIPOS'!B:H, 7, 0), """"))"),"Bloqueada") -> Bloqueada | J9: 60m | K9: 55m | L9: se desbloqueo | M9: se desbloqueo, se le instalo SO, le falta pila | N9: Finalizada OK
A10: 7 | B10: =IF(D10<>"","OT-2026-"&TEXT(ROW()-3,"000"),"") -> OT-2026-007 | C10: 46191 | D10: AA1314016444 | E10: =IFERROR(__xludf.DUMMYFUNCTION("IF(D10="""", """", IF(REGEXMATCH(TO_TEXT(D10), ""^(AA\d{10}|EDU\d{7}|\d+|SZSES10IS\d{9})$""), ""✅"", ""⚠️""))"),"✅") -> ✅ | F10: G4 | G10: Grupo 2 | H10: Lorenzetti, Axel | I10: =IFERROR(__xludf.DUMMYFUNCTION("IF(D10="""", """", IFERROR(VLOOKUP(TO_TEXT(D10), '💻 EQUIPOS'!B:H, 7, 0), """"))"),"Bloqueada") -> Bloqueada | J10: 45m | K10: 45m | L10: se desbloqueo | M10: se desbloqueo, no tiene pila, se instalo SO | N10: Finalizada OK
A11: 8 | B11: =IF(D11<>"","OT-2026-"&TEXT(ROW()-3,"000"),"") -> OT-2026-008 | C11: 46191 | D11: AA7313123510 | E11: =IFERROR(__xludf.DUMMYFUNCTION("IF(D11="""", """", IF(REGEXMATCH(TO_TEXT(D11), ""^(AA\d{10}|EDU\d{7}|\d+|SZSES10IS\d{9})$""), ""✅"", ""⚠️""))"),"✅") -> ✅ | F11: G4 | G11: Grupo 1 | H11: Terraza, Brian | I11: =IFERROR(__xludf.DUMMYFUNCTION("IF(D11="""", """", IFERROR(VLOOKUP(TO_TEXT(D11), '💻 EQUIPOS'!B:H, 7, 0), """"))"),"Bloqueada") -> Bloqueada | J11: 45m | K11: 55m | L11: se desbloqueo | M11: se desbloqueo, no tiene pila, se le debe instalar so, tiene la pantalla rota. se restauro imagen original de CI | N11: Finalizada OK
A12: 9 | B12: =IF(D12<>"","OT-2026-"&TEXT(ROW()-3,"000"),"") -> OT-2026-009 | C12: 46195 | D12: AA1053101377 | E12: =IFERROR(__xludf.DUMMYFUNCTION("IF(D12="""", """", IF(REGEXMATCH(TO_TEXT(D12), ""^(AA\d{10}|EDU\d{7}|\d+|SZSES10IS\d{9})$""), ""✅"", ""⚠️""))"),"✅") -> ✅ | F12: G4 | G12: Grupo 1 | H12: Terraza, Brian | I12: =IFERROR(__xludf.DUMMYFUNCTION("IF(D12="""", """", IFERROR(VLOOKUP(TO_TEXT(D12), '💻 EQUIPOS'!B:H, 7, 0), """"))"),"Bloqueada") -> Bloqueada | J12: 50m | K12: 60m | L12: se desbloqueo | M12: pende, se desbloqueo y falta la bateria | N12: Finalizada OK
A13: 10 | B13: =IF(D13<>"","OT-2026-"&TEXT(ROW()-3,"000"),"") -> OT-2026-010 | C13: 46195 | D13: AA8313127584 | E13: =IFERROR(__xludf.DUMMYFUNCTION("IF(D13="""", """", IF(REGEXMATCH(TO_TEXT(D13), ""^(AA\d{10}|EDU\d{7}|\d+|SZSES10IS\d{9})$""), ""✅"", ""⚠️""))"),"✅") -> ✅ | F13: G4 | G13: Grupo 2 | H13: Mottin, Francisco | I13: =IFERROR(__xludf.DUMMYFUNCTION("IF(D13="""", """", IFERROR(VLOOKUP(TO_TEXT(D13), '💻 EQUIPOS'!B:H, 7, 0), """"))"),"Bloqueada") -> Bloqueada | J13: 60m | L13: se desbloqueo | M13: prende, esta blequeada, pero no prende pantalla | N13: Finalizada OK
A14: 11 | B14: =IF(D14<>"","OT-2026-"&TEXT(ROW()-3,"000"),"") -> OT-2026-011 | C14: 46195 | D14: AA4313133415 | E14: =IFERROR(__xludf.DUMMYFUNCTION("IF(D14="""", """", IF(REGEXMATCH(TO_TEXT(D14), ""^(AA\d{10}|EDU\d{7}|\d+|SZSES10IS\d{9})$""), ""✅"", ""⚠️""))"),"✅") -> ✅ | F14: G4 | G14: Grupo 1 | H14: Kovach, Ludmila | I14: =IFERROR(__xludf.DUMMYFUNCTION("IF(D14="""", """", IFERROR(VLOOKUP(TO_TEXT(D14), '💻 EQUIPOS'!B:H, 7, 0), """"))"),"Bloqueada") -> Bloqueada | J14: 60m | L14: se desbloqueo | M14: no tiene teclado, no tiene bateria, se desbloqueo, hace falta sistema operativo y se cambio el disco duro, no le anda la pantalla, se traba en la instalacion de SO | N14: Pendiente
A15: 12 | B15: =IF(D15<>"","OT-2026-"&TEXT(ROW()-3,"000"),"") -> OT-2026-012 | C15: 46195 | D15: AA2183061905 | E15: =IFERROR(__xludf.DUMMYFUNCTION("IF(D15="""", """", IF(REGEXMATCH(TO_TEXT(D15), ""^(AA\d{10}|EDU\d{7}|\d+|SZSES10IS\d{9})$""), ""✅"", ""⚠️""))"),"✅") -> ✅ | F15: G4 | G15: Grupo 1 | H15: Terraza, Brian | I15: =IFERROR(__xludf.DUMMYFUNCTION("IF(D15="""", """", IFERROR(VLOOKUP(TO_TEXT(D15), '💻 EQUIPOS'!B:H, 7, 0), """"))"),"Bloqueada") -> Bloqueada | J15: 60m | L15: se desbloqueo | M15: no tiene teclado, no enciende, tenia un cable suelto, asi que puede ser que por eso no enciende, el touch pad estaba mal conectado | N15: Finalizada OK
A16: 13 | B16: =IF(D16<>"","OT-2026-"&TEXT(ROW()-3,"000"),"") -> OT-2026-013 | C16: 46196 | D16: AA9313652710 | E16: =IFERROR(__xludf.DUMMYFUNCTION("IF(D16="""", """", IF(REGEXMATCH(TO_TEXT(D16), ""^(AA\d{10}|EDU\d{7}|\d+|SZSES10IS\d{9})$""), ""✅"", ""⚠️""))"),"✅") -> ✅ | F16: G4 | G16: Grupo 2 | H16: Pinilla, Alexis | I16: =IFERROR(__xludf.DUMMYFUNCTION("IF(D16="""", """", IFERROR(VLOOKUP(TO_TEXT(D16), '💻 EQUIPOS'!B:H, 7, 0), """"))"),"Bloqueada") -> Bloqueada | J16: 60m | K16: 55m | L16: se desbloqueo | M16: enciende, le faltan dos teclas | N16: Finalizada OK
A17: 14 | B17: =IF(D17<>"","OT-2026-"&TEXT(ROW()-3,"000"),"") -> OT-2026-014 | C17: 46196 | D17: AA5313039059 | E17: =IFERROR(__xludf.DUMMYFUNCTION("IF(D17="""", """", IF(REGEXMATCH(TO_TEXT(D17), ""^(AA\d{10}|EDU\d{7}|\d+|SZSES10IS\d{9})$""), ""✅"", ""⚠️""))"),"✅") -> ✅ | F17: G4 | G17: Grupo 2 | H17: Lorenzetti, Axel | I17: =IFERROR(__xludf.DUMMYFUNCTION("IF(D17="""", """", IFERROR(VLOOKUP(TO_TEXT(D17), '💻 EQUIPOS'!B:H, 7, 0), """"))"),"Desbloqueada") -> Desbloqueada | J17: 60m | K17: 5m | L17: se desbloqueo | M17: enciende, le falta teclado, le falta la pila, hay que cambiar la pantalla, estaba desbloqueada | N17: Finalizada OK
A18: 15 | B18: =IF(D18<>"","OT-2026-"&TEXT(ROW()-3,"000"),"") -> OT-2026-015 | C18: 46196 | D18: AA6034019513 | E18: =IFERROR(__xludf.DUMMYFUNCTION("IF(D18="""", """", IF(REGEXMATCH(TO_TEXT(D18), ""^(AA\d{10}|EDU\d{7}|\d+|SZSES10IS\d{9})$""), ""✅"", ""⚠️""))"),"✅") -> ✅ | F18: G4 | G18: Grupo 2 | H18: Lorenzetti, Axel | I18: =IFERROR(__xludf.DUMMYFUNCTION("IF(D18="""", """", IFERROR(VLOOKUP(TO_TEXT(D18), '💻 EQUIPOS'!B:H, 7, 0), """"))"),"Bloqueada") -> Bloqueada | J18: 60m | K18: 30m | L18: se desbloqueo | M18: enciende, pantalla rota | N18: Finalizada OK
A19: 16 | B19: =IF(D19<>"","OT-2026-"&TEXT(ROW()-3,"000"),"") -> OT-2026-016 | C19: 46196 | D19: AA0313635369 | E19: =IFERROR(__xludf.DUMMYFUNCTION("IF(D19="""", """", IF(REGEXMATCH(TO_TEXT(D19), ""^(AA\d{10}|EDU\d{7}|\d+|SZSES10IS\d{9})$""), ""✅"", ""⚠️""))"),"✅") -> ✅ | F19: G4 | G19: Grupo 1 | H19: Aguilera, Thiago | I19: =IFERROR(__xludf.DUMMYFUNCTION("IF(D19="""", """", IFERROR(VLOOKUP(TO_TEXT(D19), '💻 EQUIPOS'!B:H, 7, 0), """"))"),"Bloqueada") -> Bloqueada | J19: 60m | K19: 35m | L19: se desbloqueo | M19: enciende, desbloqueada, le falla el puerto USB de la drechaho | N19: Finalizada OK
A20: 17 | B20: =IF(D20<>"","OT-2026-"&TEXT(ROW()-3,"000"),"") -> OT-2026-017 | C20: 46196 | D20: AA8164091529 | E20: =IFERROR(__xludf.DUMMYFUNCTION("IF(D20="""", """", IF(REGEXMATCH(TO_TEXT(D20), ""^(AA\d{10}|EDU\d{7}|\d+|SZSES10IS\d{9})$""), ""✅"", ""⚠️""))"),"✅") -> ✅ | F20: G4 | G20: Grupo 2 | H20: Mottin, Francisco | I20: =IFERROR(__xludf.DUMMYFUNCTION("IF(D20="""", """", IFERROR(VLOOKUP(TO_TEXT(D20), '💻 EQUIPOS'!B:H, 7, 0), """"))"),"Bloqueada") -> Bloqueada | J20: 60m | K20: 60m | L20: se desbloqueo | M20: enciende, no tiene bateria, estaba desbloqueada, hay que descargarle el drive de wifi, se le tuvo que colocar un teclado | N20: Configurando
A21: 18 | B21: =IF(D21<>"","OT-2026-"&TEXT(ROW()-3,"000"),"") -> OT-2026-018 | C21: 46196 | D21: AA5314032042 | E21: =IFERROR(__xludf.DUMMYFUNCTION("IF(D21="""", """", IF(REGEXMATCH(TO_TEXT(D21), ""^(AA\d{10}|EDU\d{7}|\d+|SZSES10IS\d{9})$""), ""✅"", ""⚠️""))"),"✅") -> ✅ | F21: G4 | G21: Grupo 1 | H21: Aguilera, Thiago | I21: =IFERROR(__xludf.DUMMYFUNCTION("IF(D21="""", """", IFERROR(VLOOKUP(TO_TEXT(D21), '💻 EQUIPOS'!B:H, 7, 0), """"))"),"Bloqueada") -> Bloqueada | J21: 30m | K21: 40m | L21: se desbloqueo | M21: enciende, tiene la pantalla rota, le falta la tecla bloq mayús, no tiene boton de encendido, no butea | N21: Pendiente
A22: 19 | B22: =IF(D22<>"","OT-2026-"&TEXT(ROW()-3,"000"),"") -> OT-2026-019 | C22: 46197 | D22: AA8313652851 | E22: =IFERROR(__xludf.DUMMYFUNCTION("IF(D22="""", """", IF(REGEXMATCH(TO_TEXT(D22), ""^(AA\d{10}|EDU\d{7}|\d+|SZSES10IS\d{9})$""), ""✅"", ""⚠️""))"),"✅") -> ✅ | F22: G4 | G22: Grupo 1 | H22: Kovach, Ludmila | I22: =IFERROR(__xludf.DUMMYFUNCTION("IF(D22="""", """", IFERROR(VLOOKUP(TO_TEXT(D22), '💻 EQUIPOS'!B:H, 7, 0), """"))"),"Bloqueada") -> Bloqueada | J22: 40m | K22: 50m | L22: se desbloqueo | M22: Le falta la tecla de ordinales, tiene la pantalla rota, no tiene bateria, no da imagen, no butea. Queda de repuesto | N22: Derivada
A23: 20 | B23: =IF(D23<>"","OT-2026-"&TEXT(ROW()-3,"000"),"") -> OT-2026-020 | C23: 46197 | D23: AA1053674988 | E23: =IFERROR(__xludf.DUMMYFUNCTION("IF(D23="""", """", IF(REGEXMATCH(TO_TEXT(D23), ""^(AA\d{10}|EDU\d{7}|\d+|SZSES10IS\d{9})$""), ""✅"", ""⚠️""))"),"✅") -> ✅ | F23: G4 | G23: Grupo 1 | H23: Terraza, Brian | I23: =IFERROR(__xludf.DUMMYFUNCTION("IF(D23="""", """", IFERROR(VLOOKUP(TO_TEXT(D23), '💻 EQUIPOS'!B:H, 7, 0), """"))"),"Bloqueada") -> Bloqueada | J23: 30M | K23: 30m | L23: se desbloqueo | M23: esta desbloqueada, tiene la manija rota, no butean. Queda de repuesto | N23: Derivada
A24: 21 | B24: =IF(D24<>"","OT-2026-"&TEXT(ROW()-3,"000"),"") -> OT-2026-021 | C24: 46197 | D24: AA9313096665 | E24: =IFERROR(__xludf.DUMMYFUNCTION("IF(D24="""", """", IF(REGEXMATCH(TO_TEXT(D24), ""^(AA\d{10}|EDU\d{7}|\d+|SZSES10IS\d{9})$""), ""✅"", ""⚠️""))"),"✅") -> ✅ | F24: G4 | G24: Grupo 1 | H24: Kovach, Ludmila | I24: =IFERROR(__xludf.DUMMYFUNCTION("IF(D24="""", """", IFERROR(VLOOKUP(TO_TEXT(D24), '💻 EQUIPOS'!B:H, 7, 0), """"))"),"Bloqueada") -> Bloqueada | J24: 60m | K24: 50m | L24: se desbloqueo | M24: Estaba desbloqueado y no tenia bateria. Queda para repuesto | N24: Derivada
A25: 22 | B25: =IF(D25<>"","OT-2026-"&TEXT(ROW()-3,"000"),"") -> OT-2026-022 | C25: 46197 | D25: AA1313122997 | E25: =IFERROR(__xludf.DUMMYFUNCTION("IF(D25="""", """", IF(REGEXMATCH(TO_TEXT(D25), ""^(AA\d{10}|EDU\d{7}|\d+|SZSES10IS\d{9})$""), ""✅"", ""⚠️""))"),"✅") -> ✅ | F25: G4 | G25: Grupo 2 | H25: Mottin, Francisco | I25: =IFERROR(__xludf.DUMMYFUNCTION("IF(D25="""", """", IFERROR(VLOOKUP(TO_TEXT(D25), '💻 EQUIPOS'!B:H, 7, 0), """"))"),"SO Instalado") -> SO Instalado | J25: 30m | K25: 30m | L25: se desbloqueo | M25: Enciende, no tiene bateria | N25: Finalizada OK
A26: 23 | B26: =IF(D26<>"","OT-2026-"&TEXT(ROW()-3,"000"),"") -> OT-2026-023 | C26: 46197 | D26: AA8164087864 | E26: =IFERROR(__xludf.DUMMYFUNCTION("IF(D26="""", """", IF(REGEXMATCH(TO_TEXT(D26), ""^(AA\d{10}|EDU\d{7}|\d+|SZSES10IS\d{9})$""), ""✅"", ""⚠️""))"),"✅") -> ✅ | F26: G4 | G26: Grupo 1 | H26: Terraza, Brian | I26: =IFERROR(__xludf.DUMMYFUNCTION("IF(D26="""", """", IFERROR(VLOOKUP(TO_TEXT(D26), '💻 EQUIPOS'!B:H, 7, 0), """"))"),"Desbloqueada") -> Desbloqueada | J26: 60m | K26: 5m | L26: se desbloqueo | M26: No tiene teclado, y le falta la bateria | N26: Derivada
A27: 24 | B27: =IF(D27<>"","OT-2026-"&TEXT(ROW()-3,"000"),"") -> OT-2026-024 | C27: 46197 | D27: AA1313621268 | E27: =IFERROR(__xludf.DUMMYFUNCTION("IF(D27="""", """", IF(REGEXMATCH(TO_TEXT(D27), ""^(AA\d{10}|EDU\d{7}|\d+|SZSES10IS\d{9})$""), ""✅"", ""⚠️""))"),"✅") -> ✅ | F27: G4 | G27: Grupo 2 | H27: Mottin, Francisco | I27: =IFERROR(__xludf.DUMMYFUNCTION("IF(D27="""", """", IFERROR(VLOOKUP(TO_TEXT(D27), '💻 EQUIPOS'!B:H, 7, 0), """"))"),"Desbloqueada") -> Desbloqueada | J27: 60m | K27: 50m | L27: se desbloqueo | M27: Tenia problemas en el boton , pantalla oscura, manija rota | N27: Finalizada OK
A28: 25 | B28: =IF(D28<>"","OT-2026-"&TEXT(ROW()-3,"000"),"") -> OT-2026-025 | C28: 46197 | D28: AA7033016030 | E28: =IFERROR(__xludf.DUMMYFUNCTION("IF(D28="""", """", IF(REGEXMATCH(TO_TEXT(D28), ""^(AA\d{10}|EDU\d{7}|\d+|SZSES10IS\d{9})$""), ""✅"", ""⚠️""))"),"✅") -> ✅ | F28: G4 | G28: Grupo 2 | H28: Mottin, Francisco | I28: =IFERROR(__xludf.DUMMYFUNCTION("IF(D28="""", """", IFERROR(VLOOKUP(TO_TEXT(D28), '💻 EQUIPOS'!B:H, 7, 0), """"))"),"Bloqueada") -> Bloqueada | J28: 60m | L28: se desbloqueo | M28: enciende, no anda el monitor, cambiar el disco duro | N28: Pendiente
A29: 26 | B29: =IF(D29<>"","OT-2026-"&TEXT(ROW()-3,"000"),"") -> OT-2026-026 | C29: 46197 | D29: AA8164119582 | E29: =IFERROR(__xludf.DUMMYFUNCTION("IF(D29="""", """", IF(REGEXMATCH(TO_TEXT(D29), ""^(AA\d{10}|EDU\d{7}|\d+|SZSES10IS\d{9})$""), ""✅"", ""⚠️""))"),"✅") -> ✅ | F29: G4 | G29: Grupo 2 | H29: Mottin, Francisco | I29: =IFERROR(__xludf.DUMMYFUNCTION("IF(D29="""", """", IFERROR(VLOOKUP(TO_TEXT(D29), '💻 EQUIPOS'!B:H, 7, 0), """"))"),"Bloqueada") -> Bloqueada | J29: 60m | L29: se desbloqueo | M29: Le falta la antena de TDA | N29: Finalizada OK
A30: 27 | B30: =IF(D30<>"","OT-2026-"&TEXT(ROW()-3,"000"),"") -> OT-2026-027 | C30: 46198 | D30: AA5313128248 | E30: =IFERROR(__xludf.DUMMYFUNCTION("IF(D30="""", """", IF(REGEXMATCH(TO_TEXT(D30), ""^(AA\d{10}|EDU\d{7}|\d+|SZSES10IS\d{9})$""), ""✅"", ""⚠️""))"),"✅") -> ✅ | F30: G4 | G30: Grupo 2 | H30: Lorenzetti, Axel | I30: =IFERROR(__xludf.DUMMYFUNCTION("IF(D30="""", """", IFERROR(VLOOKUP(TO_TEXT(D30), '💻 EQUIPOS'!B:H, 7, 0), """"))"),"Bloqueada") -> Bloqueada | J30: 60m | K30: 47m | L30: se desbloqueo | M30: enciende, desbloqueada | N30: Finalizada OK
A31: 28 | B31: =IF(D31<>"","OT-2026-"&TEXT(ROW()-3,"000"),"") -> OT-2026-028 | C31: 46198 | D31: AA5313133610 | E31: =IFERROR(__xludf.DUMMYFUNCTION("IF(D31="""", """", IF(REGEXMATCH(TO_TEXT(D31), ""^(AA\d{10}|EDU\d{7}|\d+|SZSES10IS\d{9})$""), ""✅"", ""⚠️""))"),"✅") -> ✅ | F31: G4 | G31: Grupo 2 | H31: Pinilla, Alexis | I31: =IFERROR(__xludf.DUMMYFUNCTION("IF(D31="""", """", IFERROR(VLOOKUP(TO_TEXT(D31), '💻 EQUIPOS'!B:H, 7, 0), """"))"),"Bloqueada") -> Bloqueada | J31: 60m | K31: 42m | L31: se desbloqueo | M31: enciende, le falta la letra supr | N31: Finalizada OK
A32: 29 | B32: =IF(D32<>"","OT-2026-"&TEXT(ROW()-3,"000"),"") -> OT-2026-029 | C32: 46198 | D32: AA3313631371 | E32: =IFERROR(__xludf.DUMMYFUNCTION("IF(D32="""", """", IF(REGEXMATCH(TO_TEXT(D32), ""^(AA\d{10}|EDU\d{7}|\d+|SZSES10IS\d{9})$""), ""✅"", ""⚠️""))"),"✅") -> ✅ | F32: G4 | G32: Grupo 2 | H32: Pinilla, Alexis | I32: =IFERROR(__xludf.DUMMYFUNCTION("IF(D32="""", """", IFERROR(VLOOKUP(TO_TEXT(D32), '💻 EQUIPOS'!B:H, 7, 0), """"))"),"Bloqueada") -> Bloqueada | J32: 60m | K32: 60m | L32: se desbloqueo | M32: enciende, no anda la pantalla, no tiene el teclado | N32: Finalizada OK
A33: 30 | B33: =IF(D33<>"","OT-2026-"&TEXT(ROW()-3,"000"),"") -> OT-2026-030 | C33: 46198 | D33: AA8164125172 | E33: =IFERROR(__xludf.DUMMYFUNCTION("IF(D33="""", """", IF(REGEXMATCH(TO_TEXT(D33), ""^(AA\d{10}|EDU\d{7}|\d+|SZSES10IS\d{9})$""), ""✅"", ""⚠️""))"),"✅") -> ✅ | F33: G4 | G33: Grupo 2 | H33: Cáceres, Santiago | I33: =IFERROR(__xludf.DUMMYFUNCTION("IF(D33="""", """", IFERROR(VLOOKUP(TO_TEXT(D33), '💻 EQUIPOS'!B:H, 7, 0), """"))"),"Bloqueada") -> Bloqueada | J33: 60m | K33: 48m | L33: se desbloqueo | M33: enciende, desbloqueada, da imagen, anda el wifi, anda el usb, anda el teclado completo, anda el vga, anda el touchpad, anda el audio | N33: Finalizada OK
A34: 31 | B34: =IF(D34<>"","OT-2026-"&TEXT(ROW()-3,"000"),"") -> OT-2026-031 | C34: 46198 | D34: AA0326026495 | E34: =IFERROR(__xludf.DUMMYFUNCTION("IF(D34="""", """", IF(REGEXMATCH(TO_TEXT(D34), ""^(AA\d{10}|EDU\d{7}|\d+|SZSES10IS\d{9})$""), ""✅"", ""⚠️""))"),"✅") -> ✅ | F34: G5 | G34: Grupo 2 | H34: Lorenzetti, Axel | I34: =IFERROR(__xludf.DUMMYFUNCTION("IF(D34="""", """", IFERROR(VLOOKUP(TO_TEXT(D34), '💻 EQUIPOS'!B:H, 7, 0), """"))"),"Bloqueada") -> Bloqueada | J34: 60m | K34: 45m | L34: se desbloqueo | M34: enciende, pantalla rota, se la lleva el fed de berisso | N34: Finalizada OK
A35: 32 | B35: =IF(D35<>"","OT-2026-"&TEXT(ROW()-3,"000"),"") -> OT-2026-032 | C35: 46198 | D35: AA8164087878 | E35: =IFERROR(__xludf.DUMMYFUNCTION("IF(D35="""", """", IF(REGEXMATCH(TO_TEXT(D35), ""^(AA\d{10}|EDU\d{7}|\d+|SZSES10IS\d{9})$""), ""✅"", ""⚠️""))"),"✅") -> ✅ | F35: G5 | G35: Grupo 1 | H35: Aguilera, Thiago | I35: =IFERROR(__xludf.DUMMYFUNCTION("IF(D35="""", """", IFERROR(VLOOKUP(TO_TEXT(D35), '💻 EQUIPOS'!B:H, 7, 0), """"))"),"Bloqueada") -> Bloqueada | J35: 60m | K35: 60m | L35: se desbloqueo | M35: REVISA EL PROFESOR NO TOCAR, la intervino Silvio | N35: Finalizada OK
A36: 33 | B36: =IF(D36<>"","OT-2026-"&TEXT(ROW()-3,"000"),"") -> OT-2026-033 | C36: 46198 | D36: AA7861001986 | E36: =IFERROR(__xludf.DUMMYFUNCTION("IF(D36="""", """", IF(REGEXMATCH(TO_TEXT(D36), ""^(AA\d{10}|EDU\d{7}|\d+|SZSES10IS\d{9})$""), ""✅"", ""⚠️""))"),"✅") -> ✅ | F36: G8 | G36: Grupo 1 | H36: Aguilera, Thiago | I36: =IFERROR(__xludf.DUMMYFUNCTION("IF(D36="""", """", IFERROR(VLOOKUP(TO_TEXT(D36), '💻 EQUIPOS'!B:H, 7, 0), """"))"),"Bloqueada") -> Bloqueada | J36: 60m | K36: 60m | L36: se desbloqueo | M36: NO TOCAR, SE ENCARGA EL PROFESOR, la intervino Silvio | N36: Finalizada OK
A37: 34 | B37: =IF(D37<>"","OT-2026-"&TEXT(ROW()-3,"000"),"") -> OT-2026-034 | C37: 46202 | D37: AA1313122485 | E37: =IFERROR(__xludf.DUMMYFUNCTION("IF(D37="""", """", IF(REGEXMATCH(TO_TEXT(D37), ""^(AA\d{10}|EDU\d{7}|\d+|SZSES10IS\d{9})$""), ""✅"", ""⚠️""))"),"✅") -> ✅ | F37: G4 | G37: Grupo 1 | H37: Cáceres, Santiago | I37: =IFERROR(__xludf.DUMMYFUNCTION("IF(D37="""", """", IFERROR(VLOOKUP(TO_TEXT(D37), '💻 EQUIPOS'!B:H, 7, 0), """"))"),"Bloqueada") -> Bloqueada | J37: 45m | K37: 60m | L37: se desbloqueo | M37: No tiene bateria, tiene el disco dañado y esta bloqueada, se reviso el disco duro y funciona, ya se desbloqueo, da imagen, anda el wifi, anda el audio, anda el touchpad, anda el vga, anda el usb, anda el teclado | N37: Finalizada OK
A38: 35 | B38: =IF(D38<>"","OT-2026-"&TEXT(ROW()-3,"000"),"") -> OT-2026-035 | C38: 46202 | D38: AA9163603786 | E38: =IFERROR(__xludf.DUMMYFUNCTION("IF(D38="""", """", IF(REGEXMATCH(TO_TEXT(D38), ""^(AA\d{10}|EDU\d{7}|\d+|SZSES10IS\d{9})$""), ""✅"", ""⚠️""))"),"✅") -> ✅ | F38: G4 | G38: Grupo 1 | H38: Simonetti, Tomás | I38: =IFERROR(__xludf.DUMMYFUNCTION("IF(D38="""", """", IFERROR(VLOOKUP(TO_TEXT(D38), '💻 EQUIPOS'!B:H, 7, 0), """"))"),"Recibida") -> Recibida | J38: 60m | K38: 60m | L38: Se usa como respuestos | M38: Esta roto el conector de la placa madre, queda como repuesto, se esta limpiando el disco | N38: Derivada
A39: 36 | B39: =IF(D39<>"","OT-2026-"&TEXT(ROW()-3,"000"),"") -> OT-2026-036 | C39: 46202 | D39: AA6183076205 | E39: =IFERROR(__xludf.DUMMYFUNCTION("IF(D39="""", """", IF(REGEXMATCH(TO_TEXT(D39), ""^(AA\d{10}|EDU\d{7}|\d+|SZSES10IS\d{9})$""), ""✅"", ""⚠️""))"),"✅") -> ✅ | F39: G4 | G39: Grupo 1 | H39: Cáceres, Santiago | I39: =IFERROR(__xludf.DUMMYFUNCTION("IF(D39="""", """", IFERROR(VLOOKUP(TO_TEXT(D39), '💻 EQUIPOS'!B:H, 7, 0), """"))"),"Desbloqueada") -> Desbloqueada | J39: 60m | K39: 50m | L39: Esta desbloqueada, tiene el disco dañado, se le cambio el disco, ya se instalo el sistema operativo | M39: Esta dañado el grub, anda el wifi, anda el sonido, anda el touchpad, anda el teclado completo | N39: Finalizada OK
A40: 37 | B40: =IF(D40<>"","OT-2026-"&TEXT(ROW()-3,"000"),"") -> OT-2026-037 | C40: 46202 | D40: AA0313123073 | E40: =IFERROR(__xludf.DUMMYFUNCTION("IF(D40="""", """", IF(REGEXMATCH(TO_TEXT(D40), ""^(AA\d{10}|EDU\d{7}|\d+|SZSES10IS\d{9})$""), ""✅"", ""⚠️""))"),"✅") -> ✅ | F40: G4 | G40: Grupo 1 | H40: Simonetti, Tomás | I40: =IFERROR(__xludf.DUMMYFUNCTION("IF(D40="""", """", IFERROR(VLOOKUP(TO_TEXT(D40), '💻 EQUIPOS'!B:H, 7, 0), """"))"),"Bloqueada") -> Bloqueada | J40: 60m | K40: 60m | L40: Se desbloqueo, se le tiene que instalar sistema operativo | M40: Esta bloqueada y tiene la pantalla rota, no tiene bateria, anda el vga, anda el audio, anda el wifi, anda el touchpad, anda el teclado, tira error de escritura del disco | N40: Finalizada OK
...

Sheet 💻 EQUIPOS
A1: 💻 INVENTARIO DE EQUIPOS
A2: Seguimiento completo por netbook
A3: # | B3: N° de Serie | C3: Formato | D3: Generación | E3: Modelo | F3: Marca | G3: Fecha Ingreso | H3: Estado Inicial | I3: Estado Actual | J3: Grupo | K3: OT Vinculada | L3: Observaciones Técnicas | M3: Historial de Estados
A4: 1 | B4: AA4163047472 | C4: =IFERROR(__xludf.DUMMYFUNCTION("IF(B4="""", """", IF(REGEXMATCH(TO_TEXT(B4), ""^(AA\d{10}|EDU\d{7}|\d+|SZSES10IS\d{9})$""), ""✅"", ""⚠️""))"),"✅") -> ✅ | D4: G4 | F4: EXO | G4: 46189 | H4: Bloqueada | I4: =IF(B4="", "", IFERROR(VLOOKUP(B4, '🔧 OT'!D:N, 11, 0), IF(H4<>"", H4, "Sin OT"))) -> Finalizada OK | J4: =IFERROR(__xludf.DUMMYFUNCTION("IF(B4="""", """", IFERROR(VLOOKUP(TO_TEXT(B4), INDEX(TO_TEXT('🔧 OT'!D:G)), 4, 0), ""Sin OT""))"),"Grupo 2") -> Grupo 2 | K4: OT-2026-001 | L4: esta roto el conector del teclado, disco actual es de 160, se cambia por uno de 320, queda para reutilizar un disco de 160, funciona mal la pantalla | M4: esta roto el conector del teclado,disco actual es de 160,se cambia por uno de 320,queda para reutilizar un disco de 160,funciona mal la pantalla
A5: 2 | B5: AA1183076736 | C5: =IFERROR(__xludf.DUMMYFUNCTION("IF(B5="""", """", IF(REGEXMATCH(TO_TEXT(B5), ""^(AA\d{10}|EDU\d{7}|\d+|SZSES10IS\d{9})$""), ""✅"", ""⚠️""))"),"✅") -> ✅ | D5: G4 | F5: NOVATECH | G5: 46189 | H5: Bloqueada | I5: =IF(B5="", "", IFERROR(VLOOKUP(B5, '🔧 OT'!D:N, 11, 0), IF(H5<>"", H5, "Sin OT"))) -> Finalizada OK | J5: =IFERROR(__xludf.DUMMYFUNCTION("IF(B5="""", """", IFERROR(VLOOKUP(TO_TEXT(B5), INDEX(TO_TEXT('🔧 OT'!D:G)), 4, 0), ""Sin OT""))"),"Grupo 2") -> Grupo 2 | K5: OT-2026-002 | L5: Ya se instaló el SO, No le andan las teclas X, C y V | M5: Esta desbloqueada, falta testear e instalar SO - 17-6 se testeo la maquina y ya se instaló el SO, las teclas que no funcionan son las letras X,C y V
A6: 3 | B6: AA3313139031 | C6: =IFERROR(__xludf.DUMMYFUNCTION("IF(B6="""", """", IF(REGEXMATCH(TO_TEXT(B6), ""^(AA\d{10}|EDU\d{7}|\d+|SZSES10IS\d{9})$""), ""✅"", ""⚠️""))"),"✅") -> ✅ | D6: G4 | F6: BGH | G6: 46190 | H6: Bloqueada | I6: =IF(B6="", "", IFERROR(VLOOKUP(B6, '🔧 OT'!D:N, 11, 0), IF(H6<>"", H6, "Sin OT"))) -> Finalizada OK | J6: =IFERROR(__xludf.DUMMYFUNCTION("IF(B6="""", """", IFERROR(VLOOKUP(TO_TEXT(B6), INDEX(TO_TEXT('🔧 OT'!D:G)), 4, 0), ""Sin OT""))"),"Grupo 1") -> Grupo 1 | K6: OT-2026-003 | L6: Tiene la pantalla rota, le falta una tecla el puerto USB derecho está roto | M6: 17-06 Se ha hecho el primer diagnostico: se desbloqueo, tiene la pantalla rota, le falta una tecla, el puerto USB derecho está roto, se instaló el SO y falta testear
A7: 4 | B7: AA1313665703 | C7: =IFERROR(__xludf.DUMMYFUNCTION("IF(B7="""", """", IF(REGEXMATCH(TO_TEXT(B7), ""^(AA\d{10}|EDU\d{7}|\d+|SZSES10IS\d{9})$""), ""✅"", ""⚠️""))"),"✅") -> ✅ | D7: G4 | F7: BGH | G7: 46190 | H7: Bloqueada | I7: =IF(B7="", "", IFERROR(VLOOKUP(B7, '🔧 OT'!D:N, 11, 0), IF(H7<>"", H7, "Sin OT"))) -> Derivada | J7: =IFERROR(__xludf.DUMMYFUNCTION("IF(B7="""", """", IFERROR(VLOOKUP(TO_TEXT(B7), INDEX(TO_TEXT('🔧 OT'!D:G)), 4, 0), ""Sin OT""))"),"Grupo 1") -> Grupo 1 | K7: OT-2026-004 | L7: Ya está desbloqueada,está roto el botón de encendido, está sin bateria, la carcasa está dañada, QUEDA DE REPUESTO | M7: Está roto el botón de encendido, está sin bateria, la carcasa está dañada, enciende pero no lee el disco y no da imagen
A8: 5 | B8: AA1183077623 | C8: =IFERROR(__xludf.DUMMYFUNCTION("IF(B8="""", """", IF(REGEXMATCH(TO_TEXT(B8), ""^(AA\d{10}|EDU\d{7}|\d+|SZSES10IS\d{9})$""), ""✅"", ""⚠️""))"),"✅") -> ✅ | D8: G4 | F8: NOVATECH | G8: 46191 | H8: Bloqueada | I8: =IF(B8="", "", IFERROR(VLOOKUP(B8, '🔧 OT'!D:N, 11, 0), IF(H8<>"", H8, "Sin OT"))) -> Finalizada OK | J8: =IFERROR(__xludf.DUMMYFUNCTION("IF(B8="""", """", IFERROR(VLOOKUP(TO_TEXT(B8), INDEX(TO_TEXT('🔧 OT'!D:G)), 4, 0), ""Sin OT""))"),"Grupo 2") -> Grupo 2 | K8: OT-2026-005 | L8: se desbloqueo, le falta pila | M8: se desbloqueo, enciende pero no tiene pila, se le instalo so,no se le conecto el panel tactil
A9: 6 | B9: AA6053091118 | C9: =IFERROR(__xludf.DUMMYFUNCTION("IF(B9="""", """", IF(REGEXMATCH(TO_TEXT(B9), ""^(AA\d{10}|EDU\d{7}|\d+|SZSES10IS\d{9})$""), ""✅"", ""⚠️""))"),"✅") -> ✅ | D9: G4 | F9: EDUNEC | G9: 46191 | H9: Bloqueada | I9: =IF(B9="", "", IFERROR(VLOOKUP(B9, '🔧 OT'!D:N, 11, 0), IF(H9<>"", H9, "Sin OT"))) -> Finalizada OK | J9: =IFERROR(__xludf.DUMMYFUNCTION("IF(B9="""", """", IFERROR(VLOOKUP(TO_TEXT(B9), INDEX(TO_TEXT('🔧 OT'!D:G)), 4, 0), ""Sin OT""))"),"Grupo 2") -> Grupo 2 | K9: OT-2026-006 | L9: se desbloqueo, le falta pila | M9: se desbloqueo, se le esta instalando SO, le falta pila
A10: 7 | B10: AA1314016444 | C10: =IFERROR(__xludf.DUMMYFUNCTION("IF(B10="""", """", IF(REGEXMATCH(TO_TEXT(B10), ""^(AA\d{10}|EDU\d{7}|\d+|SZSES10IS\d{9})$""), ""✅"", ""⚠️""))"),"✅") -> ✅ | D10: G4 | F10: BGH | G10: 46191 | H10: Bloqueada | I10: =IF(B10="", "", IFERROR(VLOOKUP(B10, '🔧 OT'!D:N, 11, 0), IF(H10<>"", H10, "Sin OT"))) -> Finalizada OK | J10: =IFERROR(__xludf.DUMMYFUNCTION("IF(B10="""", """", IFERROR(VLOOKUP(TO_TEXT(B10), INDEX(TO_TEXT('🔧 OT'!D:G)), 4, 0), ""Sin OT""))"),"Grupo 2") -> Grupo 2 | K10: OT-2026-007 | L10: se desbloqueo, le falta pila | M10: se desbloqueo, no tiene pila, se le va a instalar so
A11: 8 | B11: AA7313123510 | C11: =IFERROR(__xludf.DUMMYFUNCTION("IF(B11="""", """", IF(REGEXMATCH(TO_TEXT(B11), ""^(AA\d{10}|EDU\d{7}|\d+|SZSES10IS\d{9})$""), ""✅"", ""⚠️""))"),"✅") -> ✅ | D11: G4 | F11: BGH | G11: 46191 | H11: Bloqueada | I11: =IF(B11="", "", IFERROR(VLOOKUP(B11, '🔧 OT'!D:N, 11, 0), IF(H11<>"", H11, "Sin OT"))) -> Finalizada OK | J11: =IFERROR(__xludf.DUMMYFUNCTION("IF(B11="""", """", IFERROR(VLOOKUP(TO_TEXT(B11), INDEX(TO_TEXT('🔧 OT'!D:G)), 4, 0), ""Sin OT""))"),"Grupo 1") -> Grupo 1 | K11: OT-2026-008 | L11: Esta desbloqueada, no tiene bateria, le fallan los puertos USB | M11: se desbloqueo, no tiene pila, se le va a instalar so, tiene la pantalla rota, se restauro imagen original de CI
A12: 9 | B12: AA1053101377 | C12: =IFERROR(__xludf.DUMMYFUNCTION("IF(B12="""", """", IF(REGEXMATCH(TO_TEXT(B12), ""^(AA\d{10}|EDU\d{7}|\d+|SZSES10IS\d{9})$""), ""✅"", ""⚠️""))"),"✅") -> ✅ | D12: G4 | F12: EDUNEC | G12: 46195 | H12: Bloqueada | I12: =IF(B12="", "", IFERROR(VLOOKUP(B12, '🔧 OT'!D:N, 11, 0), IF(H12<>"", H12, "Sin OT"))) -> Finalizada OK | J12: =IFERROR(__xludf.DUMMYFUNCTION("IF(B12="""", """", IFERROR(VLOOKUP(TO_TEXT(B12), INDEX(TO_TEXT('🔧 OT'!D:G)), 4, 0), ""Sin OT""))"),"Grupo 1") -> Grupo 1 | K12: OT-2026-009 | L12: No tiene teclado | M12: Se desbloqueo
A13: 10 | B13: AA8313127584 | C13: =IFERROR(__xludf.DUMMYFUNCTION("IF(B13="""", """", IF(REGEXMATCH(TO_TEXT(B13), ""^(AA\d{10}|EDU\d{7}|\d+|SZSES10IS\d{9})$""), ""✅"", ""⚠️""))"),"✅") -> ✅ | D13: G4 | F13: BGH | G13: 46195 | H13: Bloqueada | I13: =IF(B13="", "", IFERROR(VLOOKUP(B13, '🔧 OT'!D:N, 11, 0), IF(H13<>"", H13, "Sin OT"))) -> Finalizada OK | J13: =IFERROR(__xludf.DUMMYFUNCTION("IF(B13="""", """", IFERROR(VLOOKUP(TO_TEXT(B13), INDEX(TO_TEXT('🔧 OT'!D:G)), 4, 0), ""Sin OT""))"),"Grupo 2") -> Grupo 2 | K13: OT-2026-010 | L13: No enciende, aun despues del chequeo | M13: Se cambio el disco duro
A14: 11 | B14: AA4313133415 | C14: =IFERROR(__xludf.DUMMYFUNCTION("IF(B14="""", """", IF(REGEXMATCH(TO_TEXT(B14), ""^(AA\d{10}|EDU\d{7}|\d+|SZSES10IS\d{9})$""), ""✅"", ""⚠️""))"),"✅") -> ✅ | D14: G4 | F14: BGH | G14: 46195 | H14: Bloqueada | I14: =IF(B14="", "", IFERROR(VLOOKUP(B14, '🔧 OT'!D:N, 11, 0), IF(H14<>"", H14, "Sin OT"))) -> Pendiente | J14: =IFERROR(__xludf.DUMMYFUNCTION("IF(B14="""", """", IFERROR(VLOOKUP(TO_TEXT(B14), INDEX(TO_TEXT('🔧 OT'!D:G)), 4, 0), ""Sin OT""))"),"Grupo 1") -> Grupo 1 | K14: OT-2026-011 | L14: no tiene teclado, no tiene bateria ,se desbloqueo,se cambio disco duro,no anda pantalla,se traba en istalacion SO | M14: Esta desbloqueada
A15: 12 | B15: AA2183061905 | C15: =IFERROR(__xludf.DUMMYFUNCTION("IF(B15="""", """", IF(REGEXMATCH(TO_TEXT(B15), ""^(AA\d{10}|EDU\d{7}|\d+|SZSES10IS\d{9})$""), ""✅"", ""⚠️""))"),"✅") -> ✅ | D15: G4 | F15: NOVATECH | G15: 46195 | H15: Bloqueada | I15: =IF(B15="", "", IFERROR(VLOOKUP(B15, '🔧 OT'!D:N, 11, 0), IF(H15<>"", H15, "Sin OT"))) -> Finalizada OK | J15: =IFERROR(__xludf.DUMMYFUNCTION("IF(B15="""", """", IFERROR(VLOOKUP(TO_TEXT(B15), INDEX(TO_TEXT('🔧 OT'!D:G)), 4, 0), ""Sin OT""))"),"Grupo 1") -> Grupo 1 | K15: OT-2026-012 | L15: No enciende, no tiene teclado | M15: Esta desbloqueada
A16: 13 | B16: AA9313652710 | C16: =IFERROR(__xludf.DUMMYFUNCTION("IF(B16="""", """", IF(REGEXMATCH(TO_TEXT(B16), ""^(AA\d{10}|EDU\d{7}|\d+|SZSES10IS\d{9})$""), ""✅"", ""⚠️""))"),"✅") -> ✅ | D16: G4 | F16: BGH | G16: 46196 | H16: Bloqueada | I16: =IF(B16="", "", IFERROR(VLOOKUP(B16, '🔧 OT'!D:N, 11, 0), IF(H16<>"", H16, "Sin OT"))) -> Finalizada OK | J16: =IFERROR(__xludf.DUMMYFUNCTION("IF(B16="""", """", IFERROR(VLOOKUP(TO_TEXT(B16), INDEX(TO_TEXT('🔧 OT'!D:G)), 4, 0), ""Sin OT""))"),"Grupo 2") -> Grupo 2 | K16: OT-2026-013 | L16: enciende, le faltan dos teclas | M16: se desbloqueo y se le va instalar SO
A17: 14 | B17: AA5313039059 | C17: =IFERROR(__xludf.DUMMYFUNCTION("IF(B17="""", """", IF(REGEXMATCH(TO_TEXT(B17), ""^(AA\d{10}|EDU\d{7}|\d+|SZSES10IS\d{9})$""), ""✅"", ""⚠️""))"),"✅") -> ✅ | D17: G4 | F17: BGH | G17: 46196 | H17: Desbloqueada | I17: =IF(B17="", "", IFERROR(VLOOKUP(B17, '🔧 OT'!D:N, 11, 0), IF(H17<>"", H17, "Sin OT"))) -> Finalizada OK | J17: =IFERROR(__xludf.DUMMYFUNCTION("IF(B17="""", """", IFERROR(VLOOKUP(TO_TEXT(B17), INDEX(TO_TEXT('🔧 OT'!D:G)), 4, 0), ""Sin OT""))"),"Grupo 2") -> Grupo 2 | K17: OT-2026-014 | L17: enciende, le falta teclado, pila, cambiar pantalla | M17: se desbloqueo y se le va instalar SO
A18: 15 | B18: AA6034019513 | C18: =IFERROR(__xludf.DUMMYFUNCTION("IF(B18="""", """", IF(REGEXMATCH(TO_TEXT(B18), ""^(AA\d{10}|EDU\d{7}|\d+|SZSES10IS\d{9})$""), ""✅"", ""⚠️""))"),"✅") -> ✅ | D18: G4 | F18: CORADIR | G18: 46196 | H18: Bloqueada | I18: =IF(B18="", "", IFERROR(VLOOKUP(B18, '🔧 OT'!D:N, 11, 0), IF(H18<>"", H18, "Sin OT"))) -> Finalizada OK | J18: =IFERROR(__xludf.DUMMYFUNCTION("IF(B18="""", """", IFERROR(VLOOKUP(TO_TEXT(B18), INDEX(TO_TEXT('🔧 OT'!D:G)), 4, 0), ""Sin OT""))"),"Grupo 2") -> Grupo 2 | K18: OT-2026-015 | L18: enciende, paantalla rota | M18: se desbloqueo y se le va instalar SO
A19: 16 | B19: AA0313635369 | C19: =IFERROR(__xludf.DUMMYFUNCTION("IF(B19="""", """", IF(REGEXMATCH(TO_TEXT(B19), ""^(AA\d{10}|EDU\d{7}|\d+|SZSES10IS\d{9})$""), ""✅"", ""⚠️""))"),"✅") -> ✅ | D19: G4 | F19: BGH | G19: 46196 | H19: Bloqueada | I19: =IF(B19="", "", IFERROR(VLOOKUP(B19, '🔧 OT'!D:N, 11, 0), IF(H19<>"", H19, "Sin OT"))) -> Finalizada OK | J19: =IFERROR(__xludf.DUMMYFUNCTION("IF(B19="""", """", IFERROR(VLOOKUP(TO_TEXT(B19), INDEX(TO_TEXT('🔧 OT'!D:G)), 4, 0), ""Sin OT""))"),"Grupo 1") -> Grupo 1 | K19: OT-2026-016 | L19: Enciende y le falla el puerto USB de la derecha | M19: enciende hay que desbloquearla
A20: 17 | B20: AA8164091529 | C20: =IFERROR(__xludf.DUMMYFUNCTION("IF(B20="""", """", IF(REGEXMATCH(TO_TEXT(B20), ""^(AA\d{10}|EDU\d{7}|\d+|SZSES10IS\d{9})$""), ""✅"", ""⚠️""))"),"✅") -> ✅ | D20: G4 | F20: BGH | G20: 46196 | H20: Bloqueada | I20: =IF(B20="", "", IFERROR(VLOOKUP(B20, '🔧 OT'!D:N, 11, 0), IF(H20<>"", H20, "Sin OT"))) -> Configurando | J20: =IFERROR(__xludf.DUMMYFUNCTION("IF(B20="""", """", IFERROR(VLOOKUP(TO_TEXT(B20), INDEX(TO_TEXT('🔧 OT'!D:G)), 4, 0), ""Sin OT""))"),"Grupo 2") -> Grupo 2 | K20: OT-2026-017 | L20: Se le coloco el teclado, falta cargar driver de WIFI | M20: Enciende correctamente, se desbloqueo a las 11:24 hs
A21: 18 | B21: AA5314032042 | C21: =IFERROR(__xludf.DUMMYFUNCTION("IF(B21="""", """", IF(REGEXMATCH(TO_TEXT(B21), ""^(AA\d{10}|EDU\d{7}|\d+|SZSES10IS\d{9})$""), ""✅"", ""⚠️""))"),"✅") -> ✅ | D21: G4 | F21: BGH | G21: 46196 | H21: Bloqueada | I21: =IF(B21="", "", IFERROR(VLOOKUP(B21, '🔧 OT'!D:N, 11, 0), IF(H21<>"", H21, "Sin OT"))) -> Pendiente | J21: =IFERROR(__xludf.DUMMYFUNCTION("IF(B21="""", """", IFERROR(VLOOKUP(TO_TEXT(B21), INDEX(TO_TEXT('🔧 OT'!D:G)), 4, 0), ""Sin OT""))"),"Grupo 1") -> Grupo 1 | K21: OT-2026-018 | L21: enciende, pantalla rota, le falta tecla Bloq mayus y boton de necendido,REVISA EL PROFE | M21: enciende, tiene pantalla rpa y le falta tecla Bloq mayus, se cambio RAM
A22: 19 | B22: AA8313652851 | C22: =IFERROR(__xludf.DUMMYFUNCTION("IF(B22="""", """", IF(REGEXMATCH(TO_TEXT(B22), ""^(AA\d{10}|EDU\d{7}|\d+|SZSES10IS\d{9})$""), ""✅"", ""⚠️""))"),"✅") -> ✅ | D22: G4 | F22: BGH | G22: 46197 | H22: Bloqueada | I22: =IF(B22="", "", IFERROR(VLOOKUP(B22, '🔧 OT'!D:N, 11, 0), IF(H22<>"", H22, "Sin OT"))) -> Derivada | J22: =IFERROR(__xludf.DUMMYFUNCTION("IF(B22="""", """", IFERROR(VLOOKUP(TO_TEXT(B22), INDEX(TO_TEXT('🔧 OT'!D:G)), 4, 0), ""Sin OT""))"),"Grupo 1") -> Grupo 1 | K22: OT-2026-019 | L22: Le falta la tecla de ordinales, tiene la pantalla rota, no tiene bateria, QUEDA DE REPUESTO | M22: Se desbloqueo a las 9:20 hs
